//Changes done are snake casing for self_collide for the components, snake casing for plugin tags for skid_steer_drive_controller, gazebo_ros_head_hokuyo_controller, camera_plugin

imu plugin and gps controller. 
<?xml version="1.0" ?>
<!-- =================================================================================== -->
<!-- |    This document was autogenerated by xacro from rover.urdf                     | -->
<!-- |    EDITING THIS FILE BY HAND IS NOT RECOMMENDED                                 | -->
<!-- =================================================================================== -->
<!-- This URDF was automatically created by SolidWorks to URDF Exporter! Originally created by Stephen Brawner (brawner@gmail.com) 
     Commit Version: 1.6.0-1-g15f4949  Build Version: 1.6.7594.29634
     For more information, please see http://wiki.ros.org/sw_urdf_exporter -->
<robot name="rover">
  <self_collide>true</self_collide>
  <gazebo reference="base_link">
    <material>Gazebo/Trunk</material>
    <self_collide>true</self_collide>
  </gazebo>
  <gazebo reference="Left_rocker">
    <material>Gazebo/Grey</material>
    <self_collide>true</self_collide>
  </gazebo>
  <gazebo reference="Right_rocker">
    <material>Gazebo/Grey</material>
    <self_collide>true</self_collide>
  </gazebo>
  <gazebo reference="Left_bogie">
    <material>Gazebo/DarkGrey</material>
    <self_collide>true</self_collide>
  </gazebo>
  <gazebo reference="Right_bogie">
    <material>Gazebo/DarkGrey</material>
    <self_collide>true</self_collide>
  </gazebo>
  <gazebo reference="wheel_1">
    <material>Gazebo/Trunk</material>
    <self_collide>true</self_collide>
  </gazebo>
  <gazebo reference="wheel_2">
    <material>Gazebo/Trunk</material>
    <self_collide>true</self_collide>
  </gazebo>
  <gazebo reference="wheel_3">
    <material>Gazebo/Trunk</material>
    <self_collide>true</self_collide>
  </gazebo>
  <gazebo reference="wheel_4">
    <material>Gazebo/Trunk</material>
    <self_collide>true</self_collide>
  </gazebo>
  <gazebo reference="wheel_5">
    <material>Gazebo/Trunk</material>
    <self_collide>true</self_collide>
  </gazebo>
  <gazebo reference="wheel_6">
    <material>Gazebo/Trunk</material>
    <self_collide>true</self_collide>
  </gazebo>
  <!-- old plugin -->
  <!-- <gazebo>
    <plugin filename="libgazebo_ros_diff_drive.so" name="differential_drive_controller">
      <alwaysOn>true</alwaysOn>
      <updateRate>20</updateRate>
      <leftJoint>wheel_joint_1</leftJoint>
      <rightJoint>wheel_joint_4</rightJoint>
      <rosDebugLevel>1</rosDebugLevel>
      <publishOdomTF>true</publishOdomTF>
      <publishWheelTF>false</publishWheelTF>
      <publishWheelJointState>true</publishWheelJointState>
      <wheelSeparation>0.43</wheelSeparation>
      <wheelDiameter>0.15</wheelDiameter>
      <torque>0.1</torque>
      <commandTopic>cmd_vel_filtered</commandTopic>
      <odometryTopic>odom</odometryTopic>
      <odometryFrame>odom</odometryFrame>
      <robotBaseFrame>base_link</robotBaseFrame>
    </plugin>
  </gazebo> -->
  <!-- new plugin for 4 wheels -->
  <gazebo>
    <plugin filename="libgazebo_ros_skid_steer_drive.so" name="skid_steer_drive_controller">
      <update_rate>10.0</update_rate>
      <robot_namespace>/</robot_namespace>
      <left_front_joint>wheel_joint_4</left_front_joint>
      <right_front_joint>wheel_joint_1</right_front_joint>
      <left_rear_joint>wheel_joint_6</left_rear_joint>
      <right_rear_joint>wheel_joint_3</right_rear_joint>
      <wheel_separation>0.43</wheel_separation>
      <wheel_diameter>0.215</wheel_diameter>
      <robot_base_frame>root_link</robot_base_frame>
      <torque>20</torque>
      <command_topic>cmd_vel</command_topic>
      <odometry_topic>odom</odometry_topic>
      <odometry_frame>odom</odometry_frame>
      <broadcast_tf>true</broadcast_tf>
    </plugin>
  </gazebo>
  <gazebo reference="sensor_laser">
    <sensor name="head_hokuyo_sensor" type="ray">
      <pose>0 0 0.2 0 0 0</pose>
      <visualize>false</visualize>
      <update_rate>10</update_rate>
      <ray>
        <scan>
          <horizontal>
            <samples>720</samples>
            <resolution>1</resolution>
            <min_angle>-3</min_angle>
            <max_angle>
              3
              <!-- 1.570796 -->
            </max_angle>
          </horizontal>
        </scan>
        <range>
          <min>0.20</min>
          <max>10.0</max>
          <resolution>0.01</resolution>
        </range>
        <noise>
          <type>gaussian</type>
          <mean>0.0</mean>
          <stddev>0.01</stddev>
        </noise>
      </ray>
      <plugin filename="libgazebo_ros_ray_sensor.so" name="gazebo_ros_head_hokuyo_controller">
        <topic_name>/mrt/laser/scan</topic_name>
        <frame_name>sensor_laser</frame_name>
      </plugin>
    </sensor>
  </gazebo>
  <!-- camera -->
  <gazebo reference="camera_link">
    <!-- <sensor type="camera" name="camera1"> -->
    <sensor name="camera1" type="depth">
      <update_rate>15.0</update_rate>
      <camera name="head">
        <horizontal_fov>1.3962634</horizontal_fov>
        <image>
          <width>800</width>
          <height>800</height>
          <format>B8G8R8</format>
        </image>
        <clip>
          <near>0.02</near>
          <far>300</far>
        </clip>
        <noise>
          <type>gaussian</type>
          <!-- Noise is sampled independently per pixel on each frame.
               That pixel's noise value is added to each of its color
               channels, which at that point lie in the range [0,1]. -->
          <mean>0.0</mean>
          <stddev>0.007</stddev>
        </noise>
      </camera>
      <!-- <plugin name="camera_controller" filename="libgazebo_ros_camera.so"> -->
      <!--   <alwaysOn>true</alwaysOn> -->
      <!--   <updateRate>0.0</updateRate> -->
      <!--   <cameraName>camera</cameraName> -->
      <!--   <imageTopicName>image_raw</imageTopicName> -->
      <!--   <cameraInfoTopicName>camera_info</cameraInfoTopicName> -->
      <!--   <frameName>camera_link</frameName> -->
      <!--   <hackBaseline>0.07</hackBaseline> -->
      <!--   <distortionK1>0.0</distortionK1> -->
      <!--   <distortionK2>0.0</distortionK2> -->
      <!--   <distortionK3>0.0</distortionK3> -->
      <!--   <distortionT1>0.0</distortionT1> -->
      <!--   <distortionT2>0.0</distortionT2> -->
      <!-- </plugin> -->
      <plugin filename="libgazebo_ros_openni_kinect.so" name="camera_plugin">
        <baseline>0.2</baseline>
        <always_on>true</always_on>
        <update_rate>0.0</update_rate>
        <!-- Keep this zero, update_rate in the parent <sensor> tag
          will control the frame rate. -->
        <camera_name>mrt/camera</camera_name>
        <image_topic_name>color/image_raw</image_topic_name>
        <camera_info_topic_name>color/camera_info</camera_info_topic_name>
        <depth_image_topic_name>depth/image_rect_raw</depth_image_topic_name>
        <depth_image_camera_info_topic_name>depth/camera_info</depth_image_camera_info_topic_name>
        <point_cloud_topic_name>depth/points</point_cloud_topic_name>
        <frame_name>camera_link_optical</frame_name>
        <point_cloud_cutoff>0.5</point_cloud_cutoff>
        <point_cloud_cutoff_max>7.0</point_cloud_cutoff_max>
        <distortion_k1>0</distortion_k1>
        <distortion_k2>0</distortion_k2>
        <distortion_k3>0</distortion_k3>
        <distortion_t1>0</distortion_t1>
        <distortion_t2>0</distortion_t2>
        <cx_prime>0</cx_prime>
        <cx>0</cx>
        <cy>0</cy>
        <focal_length>0</focal_length>
      </plugin>
    </sensor>
  </gazebo>
  <gazebo reference="imu_link">
    <gravity>true</gravity>
    <sensor name="imu_sensor" type="imu">
      <always_on>true</always_on>
      <update_rate>100</update_rate>
      <visualize>true</visualize>
      <topic>__default_topic__</topic>
      <plugin filename="libgazebo_ros_imu_sensor.so" name="imu_plugin">
        <topic_name>imu</topic_name>
        <body_name>imu_link</body_name>
        <update_rate_hz>10.0</update_rate_hz>
        <gaussian_noise>0.0</gaussian_noise>
        <xyz_offset>0 0 0</xyz_offset>
        <rpy_offset>0 0 0</rpy_offset>
        <frame_name>imu_link</frame_name>
        <initial_orientation_as_reference>false</initial_orientation_as_reference>
      </plugin>
      <pose>0 0 0 0 0 0</pose>
    </sensor>
  </gazebo>
  <gazebo>
    <plugin filename="libhector_gazebo_ros_gps.so" name="gps_controller">
      <always_on>true</always_on>
      <update_rate>1.0</update_rate>
      <body_name>base_link</body_name>
      <topic_name>fix</topic_name>
      <velocity_topic_name>fix_velocity</velocity_topic_name>
      <drift>0.0 0.0 0.0</drift>
      <gaussian_noise>0.0001 0.0001 0.0001</gaussian_noise>
      <velocity_drift>0 0 0</velocity_drift>
      <velocity_gaussian_noise>0.0 0.0 0.0</velocity_gaussian_noise>
    </plugin>
  </gazebo>
  <material name="black">
    <color rgba="0.0 0.0 0.0 1.0"/>
  </material>
  <material name="blue">
    <color rgba="0.203125 0.23828125 0.28515625 1.0"/>
  </material>
  <material name="green">
    <color rgba="0.0 0.8 0.0 1.0"/>
  </material>
  <material name="grey">
    <color rgba="0.2 0.2 0.2 1.0"/>
  </material>
  <material name="orange">
    <color rgba="1.0 0.423529411765 0.0392156862745 1.0"/>
  </material>
  <material name="brown">
    <color rgba="0.870588235294 0.811764705882 0.764705882353 1.0"/>
  </material>
  <material name="red">
    <color rgba="0.80078125 0.12890625 0.1328125 1.0"/>
  </material>
  <material name="white">
    <color rgba="1.0 1.0 1.0 1.0"/>
  </material>
  <link name="root_link">
  </link>
  <joint name="joint_root" type="fixed">
    <origin rpy="0 0 3.1415926" xyz="0.276421885520658 -0.526119109974194 -0.213679693338444"/>
    <parent link="root_link"/>
    <child link="base_link"/>
  </joint>
  <link name="base_link">
    <inertial>
      <origin rpy="0 0 0" xyz="0.27642 -0.52612 0.31368"/>
      <mass value="1.8895"/>
      <inertia ixx="0.018533" ixy="-1.2571E-10" ixz="2.6134E-12" iyy="0.030522" iyz="2.6137E-10" izz="0.048376"/>
    </inertial>
    <visual>
      <origin rpy="0 0 0" xyz="0 0 0"/>
      <geometry>
        <mesh filename="package://bot_description/meshes/base_link.STL"/>
      </geometry>
      <material name="">
        <color rgba="0.79216 0.81961 0.93333 1"/>
      </material>
    </visual>
    <collision>
      <origin rpy="0 0 0" xyz="0 0 0"/>
      <geometry>
        <mesh filename="package://bot_description/meshes/base_link.STL"/>
      </geometry>
    </collision>
  </link>
  <link name="sensor_laser">
    <inertial>
      <origin rpy="0 0 0" xyz="0 0 0"/>
      <mass value="1"/>
      <!-- RANDOM INERTIA BELOW -->
      <inertia ixx="0.02" ixy="0" ixz="0" iyy="0.02" iyz="0" izz="0.02"/>
    </inertial>
    <visual>
      <origin rpy="0 0 0" xyz="0 0 0"/>
      <geometry>
        <cylinder length="0.05" radius="0.05"/>
      </geometry>
      <material name="white"/>
    </visual>
    <collision>
      <origin rpy="0 0 0" xyz="0 0 0"/>
      <geometry>
        <cylinder length="0.05" radius="0.05"/>
      </geometry>
    </collision>
  </link>
  <joint name="joint_sensor_laser" type="fixed">
    <origin rpy="0 0 3.1415926" xyz="0.276421885520658 -0.526119109974194 0.413679693338444"/>
    <parent link="base_link"/>
    <child link="sensor_laser"/>
  </joint>
  <!-- Camera -->
  <link name="camera_link">
    <collision>
      <origin rpy="0 0 0" xyz="0 0 0"/>
      <geometry>
        <cylinder length="0.005" radius="0.005"/>
      </geometry>
    </collision>
    <visual>
      <origin rpy="0 0 0" xyz="0 0 0"/>
      <geometry>
        <cylinder length="0.005" radius="0.005"/>
      </geometry>
      <material name="green"/>
    </visual>
    <inertial>
      <mass value="1e-5"/>
      <origin rpy="0 0 0" xyz="0 0 0"/>
      <inertia ixx="1e-6" ixy="0" ixz="0" iyy="1e-6" iyz="0" izz="1e-6"/>
    </inertial>
  </link>
  <joint name="camera_joint" type="fixed">
    <origin rpy="0 0 3.1415926" xyz="-0.06421885520658 -0.526119109974194 0.403679693338444"/>
    <parent link="base_link"/>
    <child link="camera_link"/>
  </joint>
  <!-- generate an optical frame http://www.ros.org/reps/rep-0103.html#suffix-frames
      so that ros and opencv can operate on the camera frame correctly -->
  <joint name="camera_optical_joint" type="fixed">
    <!-- these values have to be these values otherwise the gazebo camera image
        won't be aligned properly with the frame it is supposedly originating from -->
    <origin rpy="-1.5707963267948966 0 -1.5707963267948966" xyz="0 0 0"/>
    <parent link="camera_link"/>
    <child link="camera_link_optical"/>
  </joint>
  <link name="camera_link_optical">
  </link>
  <!-- IMU -->
  <link name="imu_link">
    <collision>
      <origin rpy="0 0 0" xyz="0 0 0"/>
      <geometry>
        <cylinder length="0.05" radius="0.05"/>
      </geometry>
    </collision>
    <visual>
      <origin rpy="0 0 0" xyz="0 0 0"/>
      <geometry>
        <cylinder length="0.005" radius="0.005"/>
      </geometry>
      <material name="black"/>
    </visual>
    <inertial>
      <mass value="1e-5"/>
      <origin rpy="0 0 0" xyz="0 0 0"/>
      <inertia ixx="1e-6" ixy="0" ixz="0" iyy="1e-6" iyz="0" izz="1e-6"/>
    </inertial>
  </link>
  <joint name="imu_joint" type="fixed">
    <axis xyz="0 1 0"/>
    <origin rpy="0 0 0" xyz="0.276421885520658 -0.526119109974194 0.313679693338444"/>
    <parent link="base_link"/>
    <child link="imu_link"/>
  </joint>
  <link name="Left_rocker">
    <inertial>
      <origin rpy="0 0 0" xyz="0.167360944924866 -0.182311497446577 0.0450713948908615"/>
      <mass value="0.726872906165902"/>
      <inertia ixx="0.00239821590517036" ixy="0.00170592943816476" ixz="2.57104235529553E-18" iyy="0.00324908760666504" iyz="-1.44505695733635E-18" izz="0.00427740926676354"/>
    </inertial>
    <visual>
      <origin rpy="0 0 0" xyz="0 0 0"/>
      <geometry>
        <mesh filename="package://bot_description/meshes/Left_rocker.STL"/>
      </geometry>
      <material name="">
        <color rgba="0.792156862745098 0.819607843137255 0.933333333333333 1"/>
      </material>
    </visual>
    <collision>
      <origin rpy="0 0 0" xyz="0 0 0"/>
      <geometry>
        <mesh filename="package://bot_description/meshes/Left_rocker.STL"/>
      </geometry>
    </collision>
  </link>
  <joint name="joint1" type="continuous">
    <origin rpy="1.5708 -0.06648 0" xyz="0.29675 -0.78912 0.33409"/>
    <parent link="base_link"/>
    <child link="Left_rocker"/>
    <axis xyz="0 0 1"/>
  </joint>
  <link name="wheel_4">
    <inertial>
      <origin rpy="0 0 0" xyz="0.144438795009644 0.055848060179012 -0.115046141128507"/>
      <mass value="1.56933179481798"/>
      <inertia ixx="0.0103340900427652" ixy="0.000206732701279778" ixz="-0.00254072736757193" iyy="0.00810089358817614" iyz="-0.000233941595228793" izz="0.0109493657609546"/>
    </inertial>
    <visual>
      <origin rpy="0 0 0" xyz="-0.03 -0.035 -0.02"/>
      <geometry>
        <mesh filename="package://bot_description/meshes/wheel_4.STL"/>
      </geometry>
      <material name="">
        <color rgba="0.792156862745098 0.819607843137255 0.933333333333333 1"/>
      </material>
    </visual>
    <collision>
      <origin rpy="0 0 0" xyz="-0.03 -0.035 -0.02"/>
      <geometry>
        <mesh filename="package://bot_description/meshes/wheel_4.STL"/>
      </geometry>
      <surface>
        <friction>
          <ode>
            <mu>1.5</mu>
            <mu2>2</mu2>
            <slip1>1.5</slip1>
            <slip2>2</slip2>
          </ode>
        </friction>
      </surface>
    </collision>
  </link>
  <joint name="wheel_joint_4" type="continuous">
    <origin rpy="3.0602 -0.72361 -1.2268" xyz="0.4071 -0.34158 0.043136"/>
    <parent link="Left_rocker"/>
    <child link="wheel_4"/>
    <axis xyz="0.6621 0.060914 -0.74694"/>
  </joint>
  <link name="Left_bogie">
    <inertial>
      <origin rpy="0 0 0" xyz="-0.0191025407125499 -0.151328320402829 0.0624161568789092"/>
      <mass value="0.77472658771127"/>
      <inertia ixx="0.00197112599922037" ixy="7.13582562834437E-07" ixz="2.77626402487547E-12" iyy="0.00198480235561076" iyz="-1.49310628600756E-13" izz="0.00141940708466023"/>
    </inertial>
    <visual>
      <origin rpy="0 0 0" xyz="0 0 0"/>
      <geometry>
        <mesh filename="package://bot_description/meshes/Left_bogie.STL"/>
      </geometry>
      <material name="">
        <color rgba="0.792156862745098 0.819607843137255 0.933333333333333 1"/>
      </material>
    </visual>
    <collision>
      <origin rpy="0 0 0" xyz="0 0 0"/>
      <geometry>
        <mesh filename="package://bot_description/meshes/Left_bogie.STL"/>
      </geometry>
    </collision>
  </link>
  <joint name="joint3" type="revolute">
    <origin rpy="0 0 -0.11742" xyz="-0.23989 -0.077168 0.002"/>
    <parent link="Left_rocker"/>
    <child link="Left_bogie"/>
    <axis xyz="0 0 1"/>
    <limit effort="100" lower="-1" upper="0.7" velocity="1"/>
  </joint>
  <link name="wheel_5">
    <inertial>
      <origin rpy="0 0 0" xyz="0.13231582106083 0.0320795339443446 -0.127730464693944"/>
      <mass value="1.56933181485893"/>
      <inertia ixx="0.010334421333825" ixy="0.000206987460861856" ixz="-0.00254065913160713" iyy="0.00810063924924905" iyz="-0.000233343656992006" izz="0.0109492888124459"/>
    </inertial>
    <visual>
      <origin rpy="0 0 0" xyz="-0.01 -0.025 -0.01"/>
      <geometry>
        <mesh filename="package://bot_description/meshes/wheel_5.STL"/>
      </geometry>
      <material name="">
        <color rgba="0.792156862745098 0.819607843137255 0.933333333333333 1"/>
      </material>
    </visual>
    <collision>
      <origin rpy="0 0 0" xyz="-0.01 -0.025 -0.01"/>
      <geometry>
        <mesh filename="package://bot_description/meshes/wheel_5.STL"/>
      </geometry>
      <surface>
        <friction>
          <ode>
            <mu>1.5</mu>
            <mu2>2</mu2>
            <slip1>1.5</slip1>
            <slip2>2</slip2>
          </ode>
        </friction>
      </surface>
    </collision>
  </link>
  <joint name="wheel_joint_5" type="continuous">
    <origin rpy="3.0602 -0.72361 -2.6667" xyz="0.192 -0.195 0.041136"/>
    <parent link="Left_bogie"/>
    <child link="wheel_5"/>
    <axis xyz="0.6621 0.060914 -0.74694"/>
  </joint>
  <link name="wheel_6">
    <inertial>
      <origin rpy="0 0 0" xyz="0.123984453970486 0.0528779970602527 -0.133419336702574"/>
      <mass value="1.56933181485893"/>
      <inertia ixx="0.0103344213338249" ixy="0.000206987460861848" ixz="-0.00254065913160712" iyy="0.00810063924924902" iyz="-0.000233343656992003" izz="0.0109492888124459"/>
    </inertial>
    <visual>
      <origin rpy="0 0 0" xyz="-0.01 -0.025 -0.01"/>
      <geometry>
        <mesh filename="package://bot_description/meshes/wheel_5.STL"/>
      </geometry>
      <material name="">
        <color rgba="0.792156862745098 0.819607843137255 0.933333333333333 1"/>
      </material>
    </visual>
    <collision>
      <origin rpy="0 0 0" xyz="-0.01 -0.025 -0.01"/>
      <geometry>
        <mesh filename="package://bot_description/meshes/wheel_5.STL"/>
      </geometry>
      <surface>
        <friction>
          <ode>
            <mu>1.5</mu>
            <mu2>2</mu2>
            <slip1>1.5</slip1>
            <slip2>2</slip2>
          </ode>
        </friction>
      </surface>
    </collision>
  </link>
  <joint name="wheel_joint_6" type="continuous">
    <origin rpy="3.0602 -0.72361 -2.6667" xyz="-0.23514 -0.17514 0.041136"/>
    <parent link="Left_bogie"/>
    <child link="wheel_6"/>
    <axis xyz="0.6621 0.060914 -0.74694"/>
  </joint>
  <!-- <link
    name="ball-left-down0">
    <inertial>
      <origin
        xyz="2.07458677270456E-06 -0.0111838499137263 2.02617547698236E-07"
        rpy="0 0 0" />
      <mass
        value="0.0236792406632794" />
      <inertia
        ixx="2.57061050178732E-06"
        ixy="9.20708510051927E-11"
        ixz="-1.84149422795921E-09"
        iyy="3.59636855567973E-07"
        iyz="8.94129882814569E-12"
        izz="2.58931051687203E-06" />
    </inertial>
    <visual>
      <origin
        xyz="0 0 0"
        rpy="0 0 0" />
      <geometry>
        <mesh
          filename="package://bot_description/meshes/ball-left-down0.STL" />
      </geometry>
      <material
        name="">
        <color
          rgba="0.650980392156863 0.619607843137255 0.588235294117647 1" />
      </material>
    </visual>
    <collision>
      <origin
        xyz="0 0 0"
        rpy="0 0 0" />
      <geometry>
        <mesh
          filename="package://bot_description/meshes/ball-left-down0.STL" />
      </geometry>
    </collision>
  </link> -->
  <joint name="s-joint-8l" type="fixed">
    <origin rpy="-1.5708 0 -2.9303" xyz="0.31476 -0.27334 -0.0146"/>
    <parent link="Left_rocker"/>
    <child link="ball-left-down"/>
    <axis xyz="0 0 0"/>
  </joint>
  <link name="Right_rocker">
    <inertial>
      <origin rpy="0 0 0" xyz="0.183201205385285 -0.166386556947178 0.138928605109138"/>
      <mass value="0.726872906165903"/>
      <inertia ixx="0.00209714276306076" ixy="0.00160105452574116" ixz="6.08506179066926E-19" iyy="0.00355016074877466" iyz="4.53084220245437E-20" izz="0.00427740926676356"/>
    </inertial>
    <visual>
      <origin rpy="0 0 0" xyz="0 0 0"/>
      <geometry>
        <mesh filename="package://bot_description/meshes/Right_rocker.STL"/>
      </geometry>
      <material name="">
        <color rgba="0.792156862745098 0.819607843137255 0.933333333333333 1"/>
      </material>
    </visual>
    <collision>
      <origin rpy="0 0 0" xyz="0 0 0"/>
      <geometry>
        <mesh filename="package://bot_description/meshes/Right_rocker.STL"/>
      </geometry>
    </collision>
  </link>
  <joint name="joint2" type="continuous">
    <origin rpy="1.5708 0 0" xyz="0.29675 -0.079119 0.33409"/>
    <parent link="base_link"/>
    <child link="Right_rocker"/>
    <axis xyz="0 0 1"/>
  </joint>
  <link name="wheel_1">
    <inertial>
      <origin rpy="0 0 0" xyz="0.0262918155854199 -0.0029220689689949 -0.035977185773284"/>
      <mass value="1.56933180107679"/>
      <inertia ixx="0.0103344213329832" ixy="0.000206987461048749" ixz="-0.00254065913223699" iyy="0.0081006392481179" iyz="-0.000233343657269651" izz="0.0109492888118564"/>
    </inertial>
    <visual>
      <origin rpy="0 0 0" xyz="0 0 0"/>
      <geometry>
        <mesh filename="package://bot_description/meshes/wheel_1.STL"/>
      </geometry>
      <material name="">
        <color rgba="0.792156862745098 0.819607843137255 0.933333333333333 1"/>
      </material>
    </visual>
    <collision>
      <origin rpy="0 0 0" xyz="0 0 0"/>
      <geometry>
        <mesh filename="package://bot_description/meshes/wheel_1.STL"/>
      </geometry>
      <surface>
        <friction>
          <ode>
            <mu>1.5</mu>
            <mu2>2</mu2>
            <slip1>1.5</slip1>
            <slip2>2</slip2>
          </ode>
        </friction>
      </surface>
    </collision>
  </link>
  <!-- reversing xyz for wheel 123 -->
  <joint name="wheel_joint_1" type="continuous">
    <origin rpy="-0.081372 0.72361 -0.030811" xyz="0.43071 -0.30158 0"/>
    <parent link="Right_rocker"/>
    <child link="wheel_1"/>
    <axis xyz="-0.6621 -0.060914 0.74694"/>
  </joint>
  <link name="Right_bogie">
    <inertial>
      <origin rpy="0 0 0" xyz="-5.75209706540694E-05 -0.172763722897866 0.119583843668451"/>
      <mass value="0.774726597950145"/>
      <inertia ixx="0.00197108962638393" ixy="-9.83621083818607E-08" ixz="2.78023535343234E-12" iyy="0.00198483875975475" iyz="1.50952741755008E-14" izz="0.00141940711596369"/>
    </inertial>
    <visual>
      <origin rpy="0 0 0" xyz="0 0 0"/>
      <geometry>
        <mesh filename="package://bot_description/meshes/Right_bogie.STL"/>
      </geometry>
      <material name="">
        <color rgba="0.792156862745098 0.819607843137255 0.933333333333333 1"/>
      </material>
    </visual>
    <collision>
      <origin rpy="0 0 0" xyz="0 0 0"/>
      <geometry>
        <mesh filename="package://bot_description/meshes/Right_bogie.STL"/>
      </geometry>
    </collision>
  </link>
  <joint name="joint4" type="revolute">
    <origin rpy="0 0 0" xyz="-0.23989 -0.077168 0"/>
    <parent link="Right_rocker"/>
    <child link="Right_bogie"/>
    <axis xyz="0 0 1"/>
    <limit effort="100" lower="-1" upper="0.7" velocity="1"/>
  </joint>
  <link name="wheel_2">
    <inertial>
      <origin rpy="0 0 0" xyz="0.029232197183729 0.00711312038511042 -0.0325524060616964"/>
      <mass value="1.56933180107703"/>
      <inertia ixx="0.0103344213312556" ixy="0.000206987457978303" ixz="-0.00254065913109096" iyy="0.00810063924688358" iyz="-0.00023334366266065" izz="0.0109492888148186"/>
    </inertial>
    <visual>
      <origin rpy="0 0 0" xyz="0 0 0"/>
      <geometry>
        <mesh filename="package://bot_description/meshes/wheel_2.STL"/>
      </geometry>
      <material name="">
        <color rgba="0.792156862745098 0.819607843137255 0.933333333333333 1"/>
      </material>
    </visual>
    <collision>
      <origin rpy="0 0 0" xyz="0 0 0"/>
      <geometry>
        <mesh filename="package://bot_description/meshes/wheel_2.STL"/>
      </geometry>
      <surface>
        <friction>
          <ode>
            <mu>1.5</mu>
            <mu2>2</mu2>
            <slip1>1.5</slip1>
            <slip2>2</slip2>
          </ode>
        </friction>
      </surface>
    </collision>
  </link>
  <joint name="wheel_joint_2" type="continuous">
    <origin rpy="-0.081372 0.72361 -0.030811" xyz="0.21514 -0.21514 0"/>
    <parent link="Right_bogie"/>
    <child link="wheel_2"/>
    <axis xyz="-0.6621 -0.060914 0.74694"/>
  </joint>
  <link name="wheel_3">
    <inertial>
      <origin rpy="0 0 0" xyz="0.0292668549783096 0.00479183891094428 -0.0327109899183606"/>
      <mass value="1.56933179818944"/>
      <inertia ixx="0.0103344956883222" ixy="0.000207212259777325" ixz="-0.00254096968797141" iyy="0.00810114754510584" iyz="-0.000232962227841343" izz="0.0109487061591894"/>
    </inertial>
    <visual>
      <origin rpy="0 0 0" xyz="0 0 0"/>
      <geometry>
        <mesh filename="package://bot_description/meshes/wheel_3.STL"/>
      </geometry>
      <material name="">
        <color rgba="0.792156862745098 0.819607843137255 0.933333333333333 1"/>
      </material>
    </visual>
    <collision>
      <origin rpy="0 0 0" xyz="0 0 0"/>
      <geometry>
        <mesh filename="package://bot_description/meshes/wheel_3.STL"/>
      </geometry>
      <surface>
        <friction>
          <ode>
            <mu>1.5</mu>
            <mu2>2</mu2>
            <slip1>1.5</slip1>
            <slip2>2</slip2>
          </ode>
        </friction>
      </surface>
    </collision>
  </link>
  <joint name="wheel_joint_3" type="continuous">
    <origin rpy="-0.081372 0.72361 -0.030811" xyz="-0.21514 -0.21514 0"/>
    <parent link="Right_bogie"/>
    <child link="wheel_3"/>
    <axis xyz="-0.6621 -0.060914 0.74694"/>
  </joint>
  <!-- <link
    name="ball-right-down0">
    <inertial>
      <origin
        xyz="2.07457333400995E-06 -0.0111838499108833 2.0254998001068E-07"
        rpy="0 0 0" />
      <mass
        value="0.0236792406420234" />
      <inertia
        ixx="2.57061050226204E-06"
        ixy="9.20708307735023E-11"
        ixz="-1.8414954739775E-09"
        iyy="3.59636855997047E-07"
        iyz="8.94415600789211E-12"
        izz="2.58931051698473E-06" />
    </inertial>
    <visual>
      <origin
        xyz="0 0 0"
        rpy="0 0 0" />
      <geometry>
        <mesh
          filename="package://bot_description/meshes/ball-right-down0.STL" />
      </geometry>
      <material
        name="">
        <color
          rgba="0.650980392156863 0.619607843137255 0.588235294117647 1" />
      </material>
    </visual>
    <collision>
      <origin
        xyz="0 0 0"
        rpy="0 0 0" />
      <geometry>
        <mesh
          filename="package://bot_description/meshes/ball-right-down0.STL" />
      </geometry>
    </collision>
  </link> -->
  <joint name="s-joint-8r" type="fixed">
    <origin rpy="1.5708 0 -2.7598" xyz="0.33825 -0.24368 0.1986"/>
    <parent link="Right_rocker"/>
    <child link="ball-right-down"/>
    <axis xyz="0 0 0"/>
  </joint>
  <link name="connector-link-1">
    <inertial>
      <origin rpy="0 0 0" xyz="0.0190878780714502 0 0"/>
      <mass value="0.0199033183799962"/>
      <inertia ixx="5.50519098487145E-06" ixy="2.2946490565619E-22" ixz="-3.82219207612435E-23" iyy="5.85049834670421E-06" iyz="-7.63893023886394E-24" izz="4.40671191125244E-06"/>
    </inertial>
    <visual>
      <origin rpy="0 0 0" xyz="0 0 0"/>
      <geometry>
        <mesh filename="package://bot_description/meshes/connector-link-1.STL"/>
      </geometry>
      <material name="">
        <color rgba="0.792156862745098 0.819607843137255 0.933333333333333 1"/>
      </material>
    </visual>
    <collision>
      <origin rpy="0 0 0" xyz="0 0 0"/>
      <geometry>
        <mesh filename="package://bot_description/meshes/connector-link-1.STL"/>
      </geometry>
    </collision>
  </link>
  <joint name="fix-joint-1" type="fixed">
    <origin rpy="1.5708 0 0" xyz="0.57075 -0.57612 0.38409"/>
    <parent link="base_link"/>
    <child link="connector-link-1"/>
    <axis xyz="0 0 0"/>
  </joint>
  <link name="triangle-left">
    <inertial>
      <origin rpy="0 0 0" xyz="0.0808546587691665 -0.0336957844327703 -0.00505192020639311"/>
      <mass value="0.1522789919621831"/>
      <inertia ixx="7.76693819705009E-05" ixy="-6.57323940361056E-05" ixz="-2.19466715326036E-07" iyy="0.000274526110021768" iyz="9.14616825099291E-08" izz="0.000351313599973131"/>
    </inertial>
    <visual>
      <origin rpy="0 0 0" xyz="0 0 0"/>
      <geometry>
        <mesh filename="package://bot_description/meshes/triangle-left.STL"/>
      </geometry>
      <material name="">
        <color rgba="0.792156862745098 0.819607843137255 0.933333333333333 1"/>
      </material>
    </visual>
    <collision>
      <origin rpy="0 0 0" xyz="0 0 0"/>
      <geometry>
        <mesh filename="package://bot_description/meshes/triangle-left.STL"/>
      </geometry>
    </collision>
  </link>
  <joint name="s-joint-left" type="revolute">
    <origin rpy="1.5708 -1.5513 -1.5708" xyz="0.038 0 0"/>
    <parent link="connector-link-1"/>
    <child link="triangle-left"/>
    <axis xyz="0 0 1"/>
    <limit effort="100" lower="-1" upper="1" velocity="1"/>
  </joint>
  <link name="triangle-connector">
    <inertial>
      <origin rpy="0 0 0" xyz="0.05 5.55111512312578E-17 0.00516595949808951"/>
      <mass value="0.0443640564577731"/>
      <inertia ixx="2.39706488563509E-06" ixy="1.03922319270217E-19" ixz="-5.95432696611056E-21" iyy="6.71951537000553E-05" iyz="-7.31245077877221E-23" izz="6.88258108974862E-05"/>
    </inertial>
    <visual>
      <origin rpy="0 0 0" xyz="0.05 0 0"/>
      <geometry>
        <mesh filename="package://bot_description/meshes/triangle-connector-l.STL"/>
      </geometry>
      <material name="">
        <color rgba="0.898039215686275 0.917647058823529 0.929411764705882 1"/>
      </material>
    </visual>
    <collision>
      <origin rpy="0 0 0" xyz="0.05 0 0"/>
      <geometry>
        <mesh filename="package://bot_description/meshes/triangle-connector-l.STL"/>
      </geometry>
    </collision>
  </link>
  <!-- -0.04999 -0.1116 -0.01 -->
  <joint name="s-joint-left-down" type="revolute">
    <origin rpy="3.1416 0 -3.1221" xyz="0.0 -0.1116 -0.01"/>
    <parent link="triangle-left"/>
    <child link="triangle-connector"/>
    <axis xyz="0 0 1"/>
    <limit effort="30" lower="-1" upper="1" velocity="1"/>
  </joint>
  <!-- <gazebo>
    <plugin name="Myrobot_ClosedLoopPlugin" filename="libpegasus_gazebo_closed_loop_plugin.so">
      <joint>s-joint-left-down</joint> <child>triangle-connector</child> 
      <parent>triangle-left</parent>
    </plugin>
  </gazebo> -->
  <link name="triangle-ball-left">
    <inertial>
      <origin rpy="0 0 0" xyz="2.07458677536909E-06 -0.0111838499137585 2.0261754341E-07"/>
      <mass value="0.0236792406632795"/>
      <inertia ixx="2.57061050178732E-06" ixy="9.20708510051944E-11" ixz="-1.84149422795903E-09" iyy="3.59636855567973E-07" iyz="8.94129882837395E-12" izz="2.58931051687204E-06"/>
    </inertial>
    <visual>
      <origin rpy="0 0 0" xyz="0 0 0"/>
      <geometry>
        <mesh filename="package://bot_description/meshes/triangle-ball-left.STL"/>
      </geometry>
      <material name="">
        <color rgba="0.650980392156863 0.619607843137255 0.588235294117647 1"/>
      </material>
    </visual>
    <collision>
      <origin rpy="0 0 0" xyz="0 0 0"/>
      <geometry>
        <mesh filename="package://bot_description/meshes/triangle-ball-left.STL"/>
      </geometry>
    </collision>
  </link>
  <joint name="ball-left" type="fixed">
    <origin rpy="-1.5708 0 -0.11925" xyz="0.21 0 -0.0256"/>
    <parent link="triangle-left"/>
    <child link="triangle-ball-left"/>
    <axis xyz="0 0 0"/>
  </joint>
  <link name="socket-left">
    <inertial>
      <origin rpy="0 0 0" xyz="0.00692886977032131 0.000721743264174457 1.25486276925102E-08"/>
      <mass value="0.0295586667242852"/>
      <inertia ixx="1.10515560620637E-06" ixy="1.44945159679416E-07" ixz="-1.78818651322801E-12" iyy="3.67289086455697E-06" iyz="1.41647130464454E-12" izz="3.53209282187446E-06"/>
    </inertial>
    <visual>
      <origin rpy="0 0 0" xyz="0 0 0"/>
      <geometry>
        <mesh filename="package://bot_description/meshes/socket-left.STL"/>
      </geometry>
      <material name="">
        <color rgba="0.650980392156863 0.619607843137255 0.588235294117647 1"/>
      </material>
    </visual>
    <collision>
      <origin rpy="0 0 0" xyz="0 0 0"/>
      <geometry>
        <mesh filename="package://bot_description/meshes/socket-left.STL"/>
      </geometry>
    </collision>
  </link>
  <joint name="ball-socket-left" type="floating">
    <origin rpy="-0.89006 1.4692 -0.17888" xyz="0 0 0"/>
    <parent link="triangle-ball-left"/>
    <child link="socket-left"/>
    <axis xyz="0 0.707 0.707"/>
  </joint>
  <gazebo>
    <joint name="ball-socket-left" type="ball">
      <parent>triangle-ball-left</parent>
      <child>socket-left</child>
      <pose>0 0 0 -0.89006 1.4692 -0.17888</pose>
      <axis>
        <xyz>1 0 0</xyz>
        <limit>
          <lower>-3</lower>
          <upper>3</upper>
        </limit>
        <dynamics>
          <spring_reference>0</spring_reference>
          <spring_stiffness>0</spring_stiffness>
        </dynamics>
        <use_parent_model_frame>1</use_parent_model_frame>
      </axis>
      <axis2>
        <xyz>0 1 0</xyz>
        <limit>
          <lower>-1</lower>
          <upper>1</upper>
        </limit>
        <dynamics>
          <spring_reference>0</spring_reference>
          <spring_stiffness>0</spring_stiffness>
        </dynamics>
        <use_parent_model_frame>1</use_parent_model_frame>
      </axis2>
      <physics>
        <ode>
          <implicit_spring_damper>1</implicit_spring_damper>
          <cfm_damping>1</cfm_damping>
          <limit>
            <cfm>0</cfm>
            <erp>0.2</erp>
          </limit>
        </ode>
      </physics>
    </joint>
  </gazebo>
  <link name="left-rod">
    <inertial>
      <origin rpy="0 0 0" xyz="2.39808173319034E-14 -0.149000000000016 -1.69864122767649E-14"/>
      <mass value="0.0212057504117311"/>
      <inertia ixx="0.00012895746969134" ixy="-1.31361244357096E-19" ixz="6.7762635780344E-21" iyy="2.65071880146638E-07" iyz="5.1197971782694E-19" izz="0.00012895746969134"/>
    </inertial>
    <visual>
      <origin rpy="0 0 0" xyz="0 0 0"/>
      <geometry>
        <mesh filename="package://bot_description/meshes/left-rod.STL"/>
      </geometry>
      <material name="">
        <color rgba="1 0.501960784313725 0.501960784313725 1"/>
      </material>
    </visual>
    <collision>
      <origin rpy="0 0 0" xyz="0 0 0"/>
      <geometry>
        <mesh filename="package://bot_description/meshes/left-rod.STL"/>
      </geometry>
    </collision>
  </link>
  <joint name="s-joint-5l" type="fixed">
    <origin rpy="0 1.5252 1.5708" xyz="0 0 0"/>
    <parent link="socket-left"/>
    <child link="left-rod"/>
    <axis xyz="0 1 0"/>
  </joint>
  <link name="socket-left-down">
    <inertial>
      <origin rpy="0 0 0" xyz="-0.0240873295919037 -0.00927825613404898 1.55183480510246E-08"/>
      <mass value="0.0295586396880072"/>
      <inertia ixx="1.10515560121914E-06" ixy="1.44945047839436E-07" ixz="5.91299289208555E-13" iyy="3.67288871024403E-06" iyz="1.39544129503807E-12" izz="3.53209150489565E-06"/>
    </inertial>
    <visual>
      <origin rpy="0 0 0" xyz="0 0 0"/>
      <geometry>
        <mesh filename="package://bot_description/meshes/socket-left-down.STL"/>
      </geometry>
      <material name="">
        <color rgba="0.650980392156863 0.619607843137255 0.588235294117647 1"/>
      </material>
    </visual>
    <collision>
      <origin rpy="0 0 0" xyz="0 0 0"/>
      <geometry>
        <mesh filename="package://bot_description/meshes/socket-left-down.STL"/>
      </geometry>
    </collision>
  </link>
  <joint name="s-joint-6l" type="fixed">
    <origin rpy="2.7957 0 1.5708" xyz="0.0094076 -0.26698 0.0033907"/>
    <parent link="left-rod"/>
    <child link="socket-left-down"/>
    <axis xyz="1 0 0"/>
  </joint>
  <link name="ball-left-down">
    <inertial>
      <origin rpy="0 0 0" xyz="2.07458677270456E-06 -0.0111838499137263 2.02617547795381E-07"/>
      <mass value="0.0236792406632794"/>
      <inertia ixx="2.57061050178732E-06" ixy="9.20708510051983E-11" ixz="-1.84149422795921E-09" iyy="3.59636855567973E-07" iyz="8.94129882813713E-12" izz="2.58931051687203E-06"/>
    </inertial>
    <visual>
      <origin rpy="0 0 0" xyz="0 0 0"/>
      <geometry>
        <mesh filename="package://bot_description/meshes/ball-left-down.STL"/>
      </geometry>
      <material name="">
        <color rgba="0.650980392156863 0.619607843137255 0.588235294117647 1"/>
      </material>
    </visual>
    <collision>
      <origin rpy="0 0 0" xyz="0 0 0"/>
      <geometry>
        <mesh filename="package://bot_description/meshes/ball-left-down.STL"/>
      </geometry>
    </collision>
  </link>
  <!-- <joint
    name="s-joint-7l"
    type="continuous">
    <origin
      xyz="-0.031016 -0.01 0"
      rpy="-2.2692 -1.1462 2.3562" />
    <parent
      link="socket-left-down" />
    <child
      link="ball-left-down" />
    <axis
      xyz="0 1 0" /> -->
  <!-- user-defined false axis 0.6621 0.060914 -0.74694-->
  <!-- </joint> -->
  <gazebo>
    <joint name="s-joint-7l" type="universal">
      <parent>socket-left-down</parent>
      <child>ball-left-down</child>
      <pose>0.3162 -0.2719 -0.017 0 0 0</pose>
      <axis>
        <xyz>0 0 1</xyz>
        <limit>
          <lower>-3</lower>
          <upper>3</upper>
        </limit>
        <dynamics>
          <spring_reference>0</spring_reference>
          <spring_stiffness>0</spring_stiffness>
        </dynamics>
        <use_parent_model_frame>0</use_parent_model_frame>
      </axis>
      <axis2>
        <xyz>0 1 0</xyz>
        <limit>
          <lower>-1</lower>
          <upper>1</upper>
        </limit>
        <dynamics>
          <spring_reference>0</spring_reference>
          <spring_stiffness>0</spring_stiffness>
        </dynamics>
        <use_parent_model_frame>0</use_parent_model_frame>
      </axis2>
      <physics>
        <ode>
          <implicit_spring_damper>1</implicit_spring_damper>
          <cfm_damping>1</cfm_damping>
          <limit>
            <cfm>0</cfm>
            <erp>0.2</erp>
          </limit>
        </ode>
      </physics>
    </joint>
  </gazebo>
  <link name="connector-link-2">
    <inertial>
      <!-- "0.0190878780714503 0 0" -->
      <origin rpy="0 0 0" xyz="0.29875 0.34231 0.347"/>
      <mass value="0.0199033183799962"/>
      <inertia ixx="5.50519098487144E-06" ixy="1.33101064420802E-22" ixz="-1.62187736189962E-21" iyy="5.8504983467042E-06" iyz="-2.75337406645934E-22" izz="4.40671191125243E-06"/>
    </inertial>
    <visual>
      <origin rpy="0 0 0" xyz="0 0 0"/>
      <geometry>
        <mesh filename="package://bot_description/meshes/connector-link-2.STL"/>
      </geometry>
      <material name="">
        <color rgba="0.792156862745098 0.819607843137255 0.933333333333333 1"/>
      </material>
    </visual>
    <collision>
      <origin rpy="0 0 0" xyz="0 0 0"/>
      <geometry>
        <mesh filename="package://bot_description/meshes/connector-link-2.STL"/>
      </geometry>
    </collision>
  </link>
  <joint name="fix-joint-2" type="fixed">
    <origin rpy="1.5708 0 0" xyz="0.57075 -0.47612 0.38409"/>
    <parent link="base_link"/>
    <child link="connector-link-2"/>
    <axis xyz="0 0 0"/>
  </joint>
  <link name="triangle-right">
    <!-- -0.259403396495337 0.315319674105032 0.341802956534147 0.0808546587691665 -0.0336957844327703 -0.00505192020639311-->
    <inertial>
      <origin rpy="0 0 0" xyz="0.34 -0.347105032 -0.336802956534147"/>
      <mass value="0.151146897932714"/>
      <inertia ixx="0.000209697810225404" ixy="-0.000177445612241148" ixz="6.02356058570887E-07" iyy="0.000741116112539513" iyz="-2.43837164352351E-07" izz="0.000948432531563561"/>
    </inertial>
    <visual>
      <origin rpy="0 0 0" xyz="0.34 -0.347105032 -0.336802956534147"/>
      <geometry>
        <mesh filename="package://bot_description/meshes/triangle-right.STL"/>
      </geometry>
      <material name="">
        <color rgba="0.898039215686275 0.917647058823529 0.929411764705882 1"/>
      </material>
    </visual>
    <collision>
      <origin rpy="0 0 0" xyz="0.34 -0.347105032 -0.336802956534147"/>
      <geometry>
        <mesh filename="package://bot_description/meshes/triangle-right.STL"/>
      </geometry>
    </collision>
  </link>
  <joint name="s-joint-right" type="revolute">
    <!-- "-0.29875 -0.34231 -0.347" -->
    <origin rpy="1.5708 1.5513 1.5708" xyz="0.038 0 0"/>
    <parent link="connector-link-2"/>
    <child link="triangle-right"/>
    <axis xyz="0 0 1"/>
    <limit effort="100" lower="-1" upper="1" velocity="1"/>
  </joint>
  <!-- <link
    name="triangle-connector-r">
    <inertial>
      <origin
        xyz="0.05 0 0.00516595949808973"
        rpy="0 0 0" />
      <mass
        value="0.0443640564577731" />
      <inertia
        ixx="2.39706488563509E-06"
        ixy="1.0392846462111E-19"
        ixz="-5.96763105461838E-21"
        iyy="6.71951537000553E-05"
        iyz="-7.27665004284254E-23"
        izz="6.88258108974862E-05" />
    </inertial>
    <visual>
      <origin
        xyz="-0.05 0 0.01516595949808973"
        rpy="0 0 0" />
      <geometry>
        <mesh
          filename="package://bot_description/meshes/triangle-connector-l.STL" />
      </geometry>
      <material
        name="">
        <color
          rgba="0.898039215686275 0.917647058823529 0.929411764705882 1" />
      </material>
    </visual>
    <collision>
      <origin
        xyz="0 0 0"
        rpy="0 0 0" />
      <geometry>
        <mesh
          filename="package://bot_description/meshes/triangle-connector-l.STL" />
      </geometry>
    </collision>
  </link> -->
  <!-- -0.39024 0.23936 0.34675 -->
  <!-- <joint
    name="s-joint-right-down"
    type="revolute">
    <origin
      xyz="0.0 -0.1116 -0.01"
      rpy="0 0 -0.019521" />
    <parent
      link="triangle-right" />
    <child
      link="triangle-connector-r" />
    <axis
      xyz="0 0 1" />
    <limit
      lower="-1"
      upper="1"
      effort="100"
      velocity="1" />
  </joint> -->
  <gazebo>
    <joint name="s-joint-right-down" type="revolute">
      <parent>triangle-right</parent>
      <child>triangle-connector</child>
      <pose>0.1 0.0 0.01 3.1416 0 -3.1221</pose>
      <axis>
        <xyz>1 0 0</xyz>
        <limit>
          <lower>-30</lower>
          <upper>30</upper>
        </limit>
        <dynamics>
          <spring_reference>0</spring_reference>
          <spring_stiffness>0</spring_stiffness>
        </dynamics>
        <use_parent_model_frame>1</use_parent_model_frame>
      </axis>
      <physics>
        <ode>
          <implicit_spring_damper>1</implicit_spring_damper>
          <cfm_damping>1</cfm_damping>
          <limit>
            <cfm>0</cfm>
            <erp>0.2</erp>
          </limit>
        </ode>
      </physics>
    </joint>
  </gazebo>
  <link name="triangle-ball-right">
    <inertial>
      <origin rpy="0 0 0" xyz="2.07458677570216E-06 -0.0111838499137586 2.02617543465511E-07"/>
      <mass value="0.0236792406632795"/>
      <inertia ixx="2.57061050178732E-06" ixy="9.20708510051459E-11" ixz="-1.84149422795908E-09" iyy="3.59636855567974E-07" iyz="8.94129882843501E-12" izz="2.58931051687204E-06"/>
    </inertial>
    <visual>
      <origin rpy="0 0 0" xyz="0 0 0"/>
      <geometry>
        <mesh filename="package://bot_description/meshes/triangle-ball-right.STL"/>
      </geometry>
      <material name="">
        <color rgba="0.650980392156863 0.619607843137255 0.588235294117647 1"/>
      </material>
    </visual>
    <collision>
      <origin rpy="0 0 0" xyz="0 0 0"/>
      <geometry>
        <mesh filename="package://bot_description/meshes/triangle-ball-right.STL"/>
      </geometry>
    </collision>
  </link>
  <joint name="ball-right" type="fixed">
    <origin rpy="1.5708 0 -0.056761" xyz="0.21 0 0.0256"/>
    <parent link="triangle-right"/>
    <child link="triangle-ball-right"/>
    <axis xyz="0 0 0"/>
  </joint>
  <link name="socket-right">
    <inertial>
      <origin rpy="0 0 0" xyz="0.00692887499287914 0.000721744320446027 1.70823757916772E-08"/>
      <mass value="0.029558630160923"/>
      <inertia ixx="1.10515565135978E-06" ixy="1.44945104956428E-07" ixz="1.51117255919173E-12" iyy="3.6728879834209E-06" iyz="1.42307816563006E-12" izz="3.53209083484226E-06"/>
    </inertial>
    <visual>
      <origin rpy="0 0 0" xyz="0 0 0"/>
      <geometry>
        <mesh filename="package://bot_description/meshes/socket-right.STL"/>
      </geometry>
      <material name="">
        <color rgba="0.650980392156863 0.619607843137255 0.588235294117647 1"/>
      </material>
    </visual>
    <collision>
      <origin rpy="0 0 0" xyz="0 0 0"/>
      <geometry>
        <mesh filename="package://bot_description/meshes/socket-right.STL"/>
      </geometry>
    </collision>
  </link>
  <!-- looks good, might check again -->
  <joint name="ball-socket-right" type="floating">
    <origin rpy="-2.1439 -1.5681 2.1943" xyz="0 0 0"/>
    <parent link="triangle-ball-right"/>
    <child link="socket-right"/>
    <axis xyz="0 1 0"/>
  </joint>
  <gazebo>
    <joint name="ball-socket-right" type="ball">
      <parent>triangle-ball-right</parent>
      <child>socket-right</child>
      <pose>0 0 0 -2.1439 -1.5681 2.1943</pose>
      <axis>
        <xyz>0 1 0</xyz>
        <limit>
          <lower>-3</lower>
          <upper>3</upper>
        </limit>
        <dynamics>
          <spring_reference>0</spring_reference>
          <spring_stiffness>0</spring_stiffness>
        </dynamics>
        <use_parent_model_frame>0</use_parent_model_frame>
      </axis>
      <axis2>
        <xyz>0 0 1</xyz>
        <limit>
          <lower>-1</lower>
          <upper>1</upper>
        </limit>
        <dynamics>
          <spring_reference>0</spring_reference>
          <spring_stiffness>0</spring_stiffness>
        </dynamics>
        <use_parent_model_frame>0</use_parent_model_frame>
      </axis2>
      <physics>
        <ode>
          <implicit_spring_damper>1</implicit_spring_damper>
          <cfm_damping>1</cfm_damping>
          <limit>
            <cfm>0</cfm>
            <erp>0.2</erp>
          </limit>
        </ode>
      </physics>
    </joint>
  </gazebo>
  <link name="right-rod">
    <inertial>
      <origin rpy="0 0 0" xyz="-4.44089209850063E-16 -0.144572533027339 -4.44089209850063E-16"/>
      <mass value="0.0212057504117311"/>
      <inertia ixx="0.00012895746969134" ixy="-1.30319410375586E-19" ixz="1.35525271560688E-20" iyy="2.65071880146639E-07" iyz="-2.55542560997232E-19" izz="0.00012895746969134"/>
    </inertial>
    <visual>
      <origin rpy="0 0 0" xyz="0 0 0"/>
      <geometry>
        <mesh filename="package://bot_description/meshes/right-rod.STL"/>
      </geometry>
      <material name="">
        <color rgba="1 0.501960784313725 0.501960784313725 1"/>
      </material>
    </visual>
    <collision>
      <origin rpy="0 0 0" xyz="0 0 0"/>
      <geometry>
        <mesh filename="package://bot_description/meshes/right-rod.STL"/>
      </geometry>
    </collision>
  </link>
  <joint name="s-joint-5r" type="fixed">
    <origin rpy="0 0.46215 1.5708" xyz="0.0044275 0 0"/>
    <parent link="socket-right"/>
    <child link="right-rod"/>
    <axis xyz="0 1 0"/>
  </joint>
  <link name="socket-right-down">
    <inertial>
      <origin rpy="0 0 0" xyz="-0.0230097250802122 -0.00927825576114527 1.45507657034472E-08"/>
      <mass value="0.0295586322554704"/>
      <inertia ixx="1.10515540673767E-06" ixy="1.44945069137753E-07" ixz="-3.58261688020332E-13" iyy="3.67288825565564E-06" iyz="1.36590332483955E-12" izz="3.53209132242541E-06"/>
    </inertial>
    <visual>
      <origin rpy="0 0 0" xyz="0 0 0"/>
      <geometry>
        <mesh filename="package://bot_description/meshes/socket-right-down.STL"/>
      </geometry>
      <material name="">
        <color rgba="0.650980392156863 0.619607843137255 0.588235294117647 1"/>
      </material>
    </visual>
    <collision>
      <origin rpy="0 0 0" xyz="0 0 0"/>
      <geometry>
        <mesh filename="package://bot_description/meshes/socket-right-down.STL"/>
      </geometry>
    </collision>
  </link>
  <joint name="s-joint-6r" type="fixed">
    <origin rpy="1.1149 0 1.5708" xyz="-0.0044029 -0.26363 0.0089786"/>
    <parent link="right-rod"/>
    <child link="socket-right-down"/>
    <axis xyz="1 0 0"/>
  </joint>
  <link name="ball-right-down">
    <inertial>
      <origin rpy="0 0 0" xyz="2.07457333400995E-06 -0.0111838499108833 2.0254998001068E-07"/>
      <mass value="0.0236792406420234"/>
      <inertia ixx="2.57061050226204E-06" ixy="9.20708307735027E-11" ixz="-1.8414954739775E-09" iyy="3.59636855997047E-07" iyz="8.94415600789162E-12" izz="2.58931051698473E-06"/>
    </inertial>
    <visual>
      <origin rpy="0 0 0" xyz="0 0 0"/>
      <geometry>
        <mesh filename="package://bot_description/meshes/ball-right-down.STL"/>
      </geometry>
      <material name="">
        <color rgba="0.650980392156863 0.619607843137255 0.588235294117647 1"/>
      </material>
    </visual>
    <collision>
      <origin rpy="0 0 0" xyz="0 0 0"/>
      <geometry>
        <mesh filename="package://bot_description/meshes/ball-right-down.STL"/>
      </geometry>
    </collision>
  </link>
  <!-- <joint
    name="s-joint-7r"
    type="continuous">
    <origin
      xyz="-0.029939 -0.01 0"
      rpy="3.0227 1.1904 3.07" />
    <parent
      link="socket-right-down" />
    <child
      link="ball-right-down" />
    <axis
      xyz="0 0 1" /> -->
  <!-- user-defined false axis 0.6621 0.060914 -0.74694-->
  <!-- </joint> -->
  <gazebo>
    <joint name="s-joint-7r" type="universal">
      <parent>socket-right-down</parent>
      <child>ball-right-down</child>
      <pose>0.337 -0.2425 0.2 0 0 0</pose>
      <axis>
        <xyz>0 0 1</xyz>
        <limit>
          <lower>-3</lower>
          <upper>3</upper>
        </limit>
        <dynamics>
          <spring_reference>0</spring_reference>
          <spring_stiffness>0</spring_stiffness>
        </dynamics>
        <use_parent_model_frame>0</use_parent_model_frame>
      </axis>
      <axis2>
        <xyz>1 0 0</xyz>
        <limit>
          <lower>-1</lower>
          <upper>1</upper>
        </limit>
        <dynamics>
          <spring_reference>0</spring_reference>
          <spring_stiffness>0</spring_stiffness>
        </dynamics>
        <use_parent_model_frame>0</use_parent_model_frame>
      </axis2>
      <physics>
        <ode>
          <implicit_spring_damper>1</implicit_spring_damper>
          <cfm_damping>1</cfm_damping>
          <limit>
            <cfm>0</cfm>
            <erp>0.2</erp>
          </limit>
        </ode>
      </physics>
    </joint>
  </gazebo>
</robot>

